2022-06-23 18:07:45,515 INFO    MainThread:48081 [internal.py:wandb_internal():90] W&B internal server running at pid: 48081, started at: 2022-06-23 18:07:45.515172
2022-06-23 18:07:45,519 INFO    WriterThread:48081 [datastore.py:open_for_write():75] open: /Users/farah/Desktop/uni/DRL/RL_assignments/wandb/run-20220623_180744-qgkgpfpo/run-qgkgpfpo.wandb
2022-06-23 18:07:45,522 DEBUG   SenderThread:48081 [sender.py:send():235] send: header
2022-06-23 18:07:45,522 DEBUG   SenderThread:48081 [sender.py:send():235] send: run
2022-06-23 18:08:14,476 DEBUG   HandlerThread:48081 [handler.py:handle_request():141] handle_request: shutdown
2022-06-23 18:08:14,477 INFO    HandlerThread:48081 [handler.py:finish():806] shutting down handler
2022-06-23 18:08:14,560 INFO    WriterThread:48081 [datastore.py:close():279] close: /Users/farah/Desktop/uni/DRL/RL_assignments/wandb/run-20220623_180744-qgkgpfpo/run-qgkgpfpo.wandb
2022-06-23 18:08:18,893 ERROR   SenderThread:48081 [retry.py:__call__():126] Retry attempt failed:
Traceback (most recent call last):
  File "/Users/farah/venv/DRL/lib/python3.8/site-packages/urllib3/connectionpool.py", line 449, in _make_request
    six.raise_from(e, None)
  File "<string>", line 3, in raise_from
  File "/Users/farah/venv/DRL/lib/python3.8/site-packages/urllib3/connectionpool.py", line 444, in _make_request
    httplib_response = conn.getresponse()
  File "/usr/local/Cellar/python@3.8/3.8.13_1/Frameworks/Python.framework/Versions/3.8/lib/python3.8/http/client.py", line 1348, in getresponse
    response.begin()
  File "/usr/local/Cellar/python@3.8/3.8.13_1/Frameworks/Python.framework/Versions/3.8/lib/python3.8/http/client.py", line 316, in begin
    version, status, reason = self._read_status()
  File "/usr/local/Cellar/python@3.8/3.8.13_1/Frameworks/Python.framework/Versions/3.8/lib/python3.8/http/client.py", line 277, in _read_status
    line = str(self.fp.readline(_MAXLINE + 1), "iso-8859-1")
  File "/usr/local/Cellar/python@3.8/3.8.13_1/Frameworks/Python.framework/Versions/3.8/lib/python3.8/socket.py", line 669, in readinto
    return self._sock.recv_into(b)
  File "/usr/local/Cellar/python@3.8/3.8.13_1/Frameworks/Python.framework/Versions/3.8/lib/python3.8/ssl.py", line 1241, in recv_into
    return self.read(nbytes, buffer)
  File "/usr/local/Cellar/python@3.8/3.8.13_1/Frameworks/Python.framework/Versions/3.8/lib/python3.8/ssl.py", line 1099, in read
    return self._sslobj.read(len, buffer)
socket.timeout: The read operation timed out

During handling of the above exception, another exception occurred:

Traceback (most recent call last):
  File "/Users/farah/venv/DRL/lib/python3.8/site-packages/requests/adapters.py", line 489, in send
    resp = conn.urlopen(
  File "/Users/farah/venv/DRL/lib/python3.8/site-packages/urllib3/connectionpool.py", line 785, in urlopen
    retries = retries.increment(
  File "/Users/farah/venv/DRL/lib/python3.8/site-packages/urllib3/util/retry.py", line 550, in increment
    raise six.reraise(type(error), error, _stacktrace)
  File "/Users/farah/venv/DRL/lib/python3.8/site-packages/urllib3/packages/six.py", line 770, in reraise
    raise value
  File "/Users/farah/venv/DRL/lib/python3.8/site-packages/urllib3/connectionpool.py", line 703, in urlopen
    httplib_response = self._make_request(
  File "/Users/farah/venv/DRL/lib/python3.8/site-packages/urllib3/connectionpool.py", line 451, in _make_request
    self._raise_timeout(err=e, url=url, timeout_value=read_timeout)
  File "/Users/farah/venv/DRL/lib/python3.8/site-packages/urllib3/connectionpool.py", line 340, in _raise_timeout
    raise ReadTimeoutError(
urllib3.exceptions.ReadTimeoutError: HTTPSConnectionPool(host='api.wandb.ai', port=443): Read timed out. (read timeout=10)

During handling of the above exception, another exception occurred:

Traceback (most recent call last):
  File "/Users/farah/venv/DRL/lib/python3.8/site-packages/wandb/sdk/lib/retry.py", line 102, in __call__
    result = self._call_fn(*args, **kwargs)
  File "/Users/farah/venv/DRL/lib/python3.8/site-packages/wandb/sdk/internal/internal_api.py", line 140, in execute
    return self.client.execute(*args, **kwargs)
  File "/Users/farah/venv/DRL/lib/python3.8/site-packages/wandb/vendor/gql-0.2.0/wandb_gql/client.py", line 52, in execute
    result = self._get_result(document, *args, **kwargs)
  File "/Users/farah/venv/DRL/lib/python3.8/site-packages/wandb/vendor/gql-0.2.0/wandb_gql/client.py", line 60, in _get_result
    return self.transport.execute(document, *args, **kwargs)
  File "/Users/farah/venv/DRL/lib/python3.8/site-packages/wandb/vendor/gql-0.2.0/wandb_gql/transport/requests.py", line 38, in execute
    request = requests.post(self.url, **post_args)
  File "/Users/farah/venv/DRL/lib/python3.8/site-packages/requests/api.py", line 115, in post
    return request("post", url, data=data, json=json, **kwargs)
  File "/Users/farah/venv/DRL/lib/python3.8/site-packages/requests/api.py", line 59, in request
    return session.request(method=method, url=url, **kwargs)
  File "/Users/farah/venv/DRL/lib/python3.8/site-packages/requests/sessions.py", line 587, in request
    resp = self.send(prep, **send_kwargs)
  File "/Users/farah/venv/DRL/lib/python3.8/site-packages/requests/sessions.py", line 701, in send
    r = adapter.send(request, **kwargs)
  File "/Users/farah/venv/DRL/lib/python3.8/site-packages/requests/adapters.py", line 578, in send
    raise ReadTimeout(e, request=request)
requests.exceptions.ReadTimeout: HTTPSConnectionPool(host='api.wandb.ai', port=443): Read timed out. (read timeout=10)
2022-06-23 18:09:12,837 INFO    SenderThread:48081 [dir_watcher.py:__init__():205] watching files in: /Users/farah/Desktop/uni/DRL/RL_assignments/wandb/run-20220623_180744-qgkgpfpo/files
2022-06-23 18:09:12,837 INFO    SenderThread:48081 [sender.py:_start_run_threads():812] run started: qgkgpfpo with start time 1656000464
2022-06-23 18:09:12,837 INFO    SenderThread:48081 [sender.py:finish():1111] shutting down sender
2022-06-23 18:09:12,837 INFO    SenderThread:48081 [dir_watcher.py:finish():336] shutting down directory watcher
2022-06-23 18:09:13,840 INFO    SenderThread:48081 [dir_watcher.py:finish():366] scan: /Users/farah/Desktop/uni/DRL/RL_assignments/wandb/run-20220623_180744-qgkgpfpo/files
2022-06-23 18:09:13,840 INFO    SenderThread:48081 [dir_watcher.py:finish():380] scan save: /Users/farah/Desktop/uni/DRL/RL_assignments/wandb/run-20220623_180744-qgkgpfpo/files/config.yaml config.yaml
2022-06-23 18:09:13,840 INFO    SenderThread:48081 [file_pusher.py:finish():145] shutting down file pusher
2022-06-23 18:09:13,841 INFO    SenderThread:48081 [file_pusher.py:join():150] waiting for file pusher
2022-06-23 18:09:19,272 INFO    Thread-9  :48081 [upload_job.py:push():132] Uploaded file /Users/farah/Desktop/uni/DRL/RL_assignments/wandb/run-20220623_180744-qgkgpfpo/files/config.yaml
2022-06-23 18:09:20,537 INFO    MainThread:48081 [internal.py:handle_exit():80] Internal process exited
